Workbook

Sheet trades_lookback29_mktvol21_2026
A1: date | B1: action | C1: ticker | D1: execution_price | E1: market_price | F1: quantity | G1: quantity_signed | H1: cash_balance | I1: position_value | J1: total_value
A2: 45993 | B2: BUY | C2: OBLG | D2: 187.22 | E2: 187.22 | F2: 17636.96 | G2: 17636.96 | H2: 0 | I2: 3301992 | J2: 3301992
A3: 45999 | B3: BUY | C3: LQDT | D3: 1.87 | E3: 1.87 | F3: 1771220.4 | G3: 1771220.4 | H3: 0 | I3: 3305805.6 | J3: 3305805.6 | K3: =(J3-$J$2)/$J$2*100 -> 0.11549634
A4: 46000 | B4: BUY | C4: EQMX | D4: 139.2 | E4: 139.2 | F4: 23759.58 | G4: 23759.58 | H4: 0 | I4: 3307333.3 | J4: 3307333.3 | K4: =(J4-$J$2)/$J$2*100 -> 0.16175993
A5: 46001 | B5: BUY | C5: OBLG | D5: 188.16 | E5: 188.16 | F5: 17570.57 | G5: 17570.57 | H5: 0 | I5: 3306078.8 | J5: 3306078.8 | K5: =(J5-$J$2)/$J$2*100 -> 0.12376983
A6: 46002 | B6: BUY | C6: EQMX | D6: 141.1 | E6: 141.1 | F6: 23425.3 | G6: 23425.3 | H6: 0 | I6: 3305309.6 | J6: 3305309.6 | K6: =(J6-$J$2)/$J$2*100 -> 0.10047299
A7: 46003 | B7: BUY | C7: OBLG | D7: 188.62 | E7: 188.62 | F7: 17225.23 | G7: 17225.23 | H7: 0 | I7: 3249023.6 | J7: 3249023.6 | K7: =(J7-$J$2)/$J$2*100 -> -1.604135
A8: 46008 | B8: BUY | C8: GOLD | D8: 2.73 | E8: 2.73 | F8: 1191755.6 | G8: 1191755.6 | H8: 0 | I8: 3258259.7 | J8: 3258259.7 | K8: =(J8-$J$2)/$J$2*100 -> -1.3244211
A9: 46009 | B9: BUY | C9: OBLG | D9: 189.56 | E9: 189.56 | F9: 17210.2 | G9: 17210.2 | H9: 0 | I9: 3262365.3 | J9: 3262365.3 | K9: =(J9-$J$2)/$J$2*100 -> -1.200085
A10: 46010 | B10: BUY | C10: GOLD | D10: 2.73 | E10: 2.73 | F10: 1192930.6 | G10: 1192930.6 | H10: 0 | I10: 3256104.1 | J10: 3256104.1 | K10: =(J10-$J$2)/$J$2*100 -> -1.3897014
A11: 46020 | B11: BUY | C11: OBLG | D11: 190.24 | E11: 190.24 | F11: 16845.79 | G11: 16845.79 | H11: 0 | I11: 3204743.7 | J11: 3204743.7 | K11: =(J11-$J$2)/$J$2*100 -> -2.9451392
A12: 46044 | B12: BUY | C12: GOLD | D12: 2.97 | E12: 2.97 | F12: 1086843.8 | G12: 1086843.8 | H12: 0 | I12: 3227926 | J12: 3227926 | K12: =(J12-$J$2)/$J$2*100 -> -2.2430687
A13: 46049 | B13: BUY | C13: OBLG | D13: 192.44 | E13: 192.44 | F13: 17583.77 | G13: 17583.77 | H13: 0 | I13: 3383820.1 | J13: 3383820.1 | K13: =(J13-$J$2)/$J$2*100 -> 2.4781441
A14: 46051 | B14: BUY | C14: LQDT | D14: 1.91 | E14: 1.91 | F14: 1771977.6 | G14: 1771977.6 | H14: 0 | I14: 3381642.1 | J14: 3381642.1 | K14: =(J14-$J$2)/$J$2*100 -> 2.4121833
... A18: 46066 | B18: BUY | C18: LQDT | D18: 1.92 | E18: 1.92 | F18: 1776800.9 | G18: 1776800.9 | H18: 0 | I18: 3415011.3 | J18: 3415011.3 | K18: =(J18-$J$2)/$J$2*100 -> 3.4227609

Sheet EQMX
A1: TRADEDATE | B1: OPEN | C1: HIGH | D1: LOW | E1: CLOSE | F1: VOLUME | G1: result
A2: 45993 | B2: 137.15 | C2: 137.75 | D2: 136.1 | E2: 136.95 | F2: 1501611
A3: 45994 | B3: 135.35 | C3: 135.75 | D3: 134 | E3: 135.55 | F3: 898823 | G3: =(E3-$E$2)/$E$2*100 -> -1.0222709
A4: 45995 | B4: 135.95 | C4: 136.55 | D4: 135.4 | E4: 135.5 | F4: 462916 | G4: =(E4-$E$2)/$E$2*100 -> -1.0587806
A5: 45996 | B5: 135.55 | C5: 138.95 | D5: 135.55 | E5: 138.65 | F5: 1462723 | G5: =(E5-$E$2)/$E$2*100 -> 1.241329
A6: 45999 | B6: 139 | C6: 140 | D6: 137.5 | E6: 137.65 | F6: 1630418 | G6: =(E6-$E$2)/$E$2*100 -> 0.51113545
A7: 46000 | B7: 137.77 | C7: 140.11 | D7: 137.015 | E7: 138.21 | F7: 1437752.4 | G7: =(E7-$E$2)/$E$2*100 -> 0.92004381
A8: 46001 | B8: 138.16 | C8: 140.88 | D8: 137.45 | E8: 138.66 | F8: 1519903.8 | G8: =(E8-$E$2)/$E$2*100 -> 1.2486309
A9: 46002 | B9: 138.55 | C9: 141.65 | D9: 137.885 | E9: 139.11 | F9: 1602055.2 | G9: =(E9-$E$2)/$E$2*100 -> 1.577218
A10: 46003 | B10: 138.94 | C10: 142.42 | D10: 138.32 | E10: 139.56 | F10: 1684206.6 | G10: =(E10-$E$2)/$E$2*100 -> 1.905805
A11: 46006 | B11: 139.33 | C11: 143.19 | D11: 138.755 | E11: 140.01 | F11: 1766358 | G11: =(E11-$E$2)/$E$2*100 -> 2.2343921
A12: 46007 | B12: 139.72 | C12: 143.96 | D12: 139.19 | E12: 140.46 | F12: 1848509.4 | G12: =(E12-$E$2)/$E$2*100 -> 2.5629792
A13: 46008 | B13: 140.11 | C13: 144.73 | D13: 139.625 | E13: 140.91 | F13: 1930660.8 | G13: =(E13-$E$2)/$E$2*100 -> 2.8915663
A14: 46009 | B14: 140.5 | C14: 145.5 | D14: 140.06 | E14: 141.36 | F14: 2012812.2 | G14: =(E14-$E$2)/$E$2*100 -> 3.2201533
... A51: 46066 | B51: 154.93 | C51: 173.99 | D51: 156.155 | E51: 158.01 | F51: 5052414 | G51: =(E51-$E$2)/$E$2*100 -> 15.377875

Sheet Sheet5
A1: TRADEDATE | B1: EQMX | C1: GOLD | D1: LQDT | E1: OBLG | F1: Strategy
A2: 45993 | B2: =VLOOKUP(A2,EQMX!A:G,7,FALSE) -> 0 | C2: =VLOOKUP(A2,GOLD!A:G,7,FALSE) -> 0 | D2: =VLOOKUP(A2,LQDT!A:G,7,FALSE) -> 0 | E2: =VLOOKUP(A2,OBLG!A:G,7,FALSE) -> 0 | F2: =VLOOKUP(A2,trades_lookback29_mktvol21_2026!A:K,11,FALSE) -> 0
A3: 45994 | B3: =VLOOKUP(A3,EQMX!A:G,7,FALSE) -> -1.0222709 | C3: =VLOOKUP(A3,GOLD!A:G,7,FALSE) -> -0.93600764 | D3: =VLOOKUP(A3,LQDT!A:G,7,FALSE) -> 0.04296917 | E3: =VLOOKUP(A3,OBLG!A:G,7,FALSE) -> 0.032047858
A4: 45995 | B4: =VLOOKUP(A4,EQMX!A:G,7,FALSE) -> -1.0587806 | C4: =VLOOKUP(A4,GOLD!A:G,7,FALSE) -> -2.139446 | D4: =VLOOKUP(A4,LQDT!A:G,7,FALSE) -> 0.080567193 | E4: =VLOOKUP(A4,OBLG!A:G,7,FALSE) -> -0.021365239
A5: 45996 | B5: =VLOOKUP(A5,EQMX!A:G,7,FALSE) -> 1.241329 | C5: =VLOOKUP(A5,GOLD!A:G,7,FALSE) -> -1.069723 | D5: =VLOOKUP(A5,LQDT!A:G,7,FALSE) -> 0.2094747 | E5: =VLOOKUP(A5,OBLG!A:G,7,FALSE) -> 0.21365239
A6: 45999 | B6: =VLOOKUP(A6,EQMX!A:G,7,FALSE) -> 0.51113545 | C6: =VLOOKUP(A6,GOLD!A:G,7,FALSE) -> -1.069723 | D6: =VLOOKUP(A6,LQDT!A:G,7,FALSE) -> 0.24707273 | E6: =VLOOKUP(A6,OBLG!A:G,7,FALSE) -> 0.11750881 | F6: =VLOOKUP(A6,trades_lookback29_mktvol21_2026!A:K,11,FALSE) -> 0.11549634
A7: 46000 | B7: =VLOOKUP(A7,EQMX!A:G,7,FALSE) -> 0.92004381 | C7: =VLOOKUP(A7,GOLD!A:G,7,FALSE) -> -0.17191977 | D7: =VLOOKUP(A7,LQDT!A:G,7,FALSE) -> 0.29541304 | E7: =VLOOKUP(A7,OBLG!A:G,7,FALSE) -> 0.14955667 | F7: =VLOOKUP(A7,trades_lookback29_mktvol21_2026!A:K,11,FALSE) -> 0.16175993
A8: 46001 | B8: =VLOOKUP(A8,EQMX!A:G,7,FALSE) -> 1.2486309 | C8: =VLOOKUP(A8,GOLD!A:G,7,FALSE) -> 1.2225406 | D8: =VLOOKUP(A8,LQDT!A:G,7,FALSE) -> 0.34375336 | E8: =VLOOKUP(A8,OBLG!A:G,7,FALSE) -> 0.50208311 | F8: =VLOOKUP(A8,trades_lookback29_mktvol21_2026!A:K,11,FALSE) -> 0.12376983
A9: 46002 | B9: =VLOOKUP(A9,EQMX!A:G,7,FALSE) -> 1.577218 | C9: =VLOOKUP(A9,GOLD!A:G,7,FALSE) -> 2.617001 | D9: =VLOOKUP(A9,LQDT!A:G,7,FALSE) -> 0.38672253 | E9: =VLOOKUP(A9,OBLG!A:G,7,FALSE) -> 0.48071787 | F9: =VLOOKUP(A9,trades_lookback29_mktvol21_2026!A:K,11,FALSE) -> 0.10047299
A10: 46003 | B10: =VLOOKUP(A10,EQMX!A:G,7,FALSE) -> 1.905805 | C10: =VLOOKUP(A10,GOLD!A:G,7,FALSE) -> 2.9799427 | D10: =VLOOKUP(A10,LQDT!A:G,7,FALSE) -> 0.51563004 | E10: =VLOOKUP(A10,OBLG!A:G,7,FALSE) -> 0.74778336 | F10: =VLOOKUP(A10,trades_lookback29_mktvol21_2026!A:K,11,FALSE) -> -1.604135
A11: 46006 | B11: =VLOOKUP(A11,EQMX!A:G,7,FALSE) -> 2.2343921 | C11: =VLOOKUP(A11,GOLD!A:G,7,FALSE) -> 3.8777459 | D11: =VLOOKUP(A11,LQDT!A:G,7,FALSE) -> 0.55322806 | E11: =VLOOKUP(A11,OBLG!A:G,7,FALSE) -> 0.90802265
A12: 46007 | B12: =VLOOKUP(A12,EQMX!A:G,7,FALSE) -> 2.5629792 | C12: =VLOOKUP(A12,GOLD!A:G,7,FALSE) -> 3.6485196 | D12: =VLOOKUP(A12,LQDT!A:G,7,FALSE) -> 0.59619723 | E12: =VLOOKUP(A12,OBLG!A:G,7,FALSE) -> 0.92938789
A13: 46008 | B13: =VLOOKUP(A13,EQMX!A:G,7,FALSE) -> 2.8915663 | C13: =VLOOKUP(A13,GOLD!A:G,7,FALSE) -> 4.4508118 | D13: =VLOOKUP(A13,LQDT!A:G,7,FALSE) -> 0.6391664 | E13: =VLOOKUP(A13,OBLG!A:G,7,FALSE) -> 1.0362141 | F13: =VLOOKUP(A13,trades_lookback29_mktvol21_2026!A:K,11,FALSE) -> -1.3244211
A14: 46009 | B14: =VLOOKUP(A14,EQMX!A:G,7,FALSE) -> 3.2201533 | C14: =VLOOKUP(A14,GOLD!A:G,7,FALSE) -> 4.5845272 | D14: =VLOOKUP(A14,LQDT!A:G,7,FALSE) -> 0.68213557 | E14: =VLOOKUP(A14,OBLG!A:G,7,FALSE) -> 1.2498665 | F14: =VLOOKUP(A14,trades_lookback29_mktvol21_2026!A:K,11,FALSE) -> -1.200085
A15: 46010 | B15: =VLOOKUP(A15,EQMX!A:G,7,FALSE) -> 3.5487404 | C15: =VLOOKUP(A15,GOLD!A:G,7,FALSE) -> 4.2788921 | D15: =VLOOKUP(A15,LQDT!A:G,7,FALSE) -> 0.80567193 | E15: =VLOOKUP(A15,OBLG!A:G,7,FALSE) -> 1.0575793 | F15: =VLOOKUP(A15,trades_lookback29_mktvol21_2026!A:K,11,FALSE) -> -1.3897014
A16: 46013 | B16: =VLOOKUP(A16,EQMX!A:G,7,FALSE) -> 3.8773275 | C16: =VLOOKUP(A16,GOLD!A:G,7,FALSE) -> 4.6227316 | D16: =VLOOKUP(A16,LQDT!A:G,7,FALSE) -> 0.85401225 | E16: =VLOOKUP(A16,OBLG!A:G,7,FALSE) -> 0.95075312
A17: 46014 | B17: =VLOOKUP(A17,EQMX!A:G,7,FALSE) -> 4.2059146 | C17: =VLOOKUP(A17,GOLD!A:G,7,FALSE) -> 4.947469 | D17: =VLOOKUP(A17,LQDT!A:G,7,FALSE) -> 0.89698142 | E17: =VLOOKUP(A17,OBLG!A:G,7,FALSE) -> 0.68368764
A18: 46015 | B18: =VLOOKUP(A18,EQMX!A:G,7,FALSE) -> 4.5345016 | C18: =VLOOKUP(A18,GOLD!A:G,7,FALSE) -> 5.1002865 | D18: =VLOOKUP(A18,LQDT!A:G,7,FALSE) -> 0.93995059 | E18: =VLOOKUP(A18,OBLG!A:G,7,FALSE) -> 0.70505288
A19: 46016 | B19: =VLOOKUP(A19,EQMX!A:G,7,FALSE) -> 4.8630887 | C19: =VLOOKUP(A19,GOLD!A:G,7,FALSE) -> 4.0305635 | D19: =VLOOKUP(A19,LQDT!A:G,7,FALSE) -> 0.98291976 | E19: =VLOOKUP(A19,OBLG!A:G,7,FALSE) -> 1.0148488
A20: 46017 | B20: =VLOOKUP(A20,EQMX!A:G,7,FALSE) -> 5.1916758 | C20: =VLOOKUP(A20,GOLD!A:G,7,FALSE) -> 5.1766953 | D20: =VLOOKUP(A20,LQDT!A:G,7,FALSE) -> 1.1118273 | E20: =VLOOKUP(A20,OBLG!A:G,7,FALSE) -> 1.2925969
A21: 46020 | B21: =VLOOKUP(A21,EQMX!A:G,7,FALSE) -> 5.5202629 | C21: =VLOOKUP(A21,GOLD!A:G,7,FALSE) -> 2.6361032 | D21: =VLOOKUP(A21,LQDT!A:G,7,FALSE) -> 1.1547964 | E21: =VLOOKUP(A21,OBLG!A:G,7,FALSE) -> 1.6130755 | F21: =VLOOKUP(A21,trades_lookback29_mktvol21_2026!A:K,11,FALSE) -> -2.9451392
A22: 46021 | B22: =VLOOKUP(A22,EQMX!A:G,7,FALSE) -> 5.8488499 | C22: =VLOOKUP(A22,GOLD!A:G,7,FALSE) -> 4.5845272 | D22: =VLOOKUP(A22,LQDT!A:G,7,FALSE) -> 1.4179826 | E22: =VLOOKUP(A22,OBLG!A:G,7,FALSE) -> 2.189937
A23: 46027 | B23: =VLOOKUP(A23,EQMX!A:G,7,FALSE) -> 6.177437 | C23: =VLOOKUP(A23,GOLD!A:G,7,FALSE) -> 7.8892073 | D23: =VLOOKUP(A23,LQDT!A:G,7,FALSE) -> 1.4609518 | E23: =VLOOKUP(A23,OBLG!A:G,7,FALSE) -> 2.4890503
A24: 46028 | B24: =VLOOKUP(A24,EQMX!A:G,7,FALSE) -> 6.5060241 | C24: =VLOOKUP(A24,GOLD!A:G,7,FALSE) -> 8.5004776 | D24: =VLOOKUP(A24,LQDT!A:G,7,FALSE) -> 1.5468901 | E24: =VLOOKUP(A24,OBLG!A:G,7,FALSE) -> 2.4997329
A25: 46030 | B25: =VLOOKUP(A25,EQMX!A:G,7,FALSE) -> 6.8346112 | C25: =VLOOKUP(A25,GOLD!A:G,7,FALSE) -> 7.5453677 | D25: =VLOOKUP(A25,LQDT!A:G,7,FALSE) -> 1.5844881 | E25: =VLOOKUP(A25,OBLG!A:G,7,FALSE) -> 2.4570025
A26: 46031 | B26: =VLOOKUP(A26,EQMX!A:G,7,FALSE) -> 7.1631982 | C26: =VLOOKUP(A26,GOLD!A:G,7,FALSE) -> 8.0038204 | D26: =VLOOKUP(A26,LQDT!A:G,7,FALSE) -> 1.7187668 | E26: =VLOOKUP(A26,OBLG!A:G,7,FALSE) -> 2.6172417
A27: 46034 | B27: =VLOOKUP(A27,EQMX!A:G,7,FALSE) -> 7.4917853 | C27: =VLOOKUP(A27,GOLD!A:G,7,FALSE) -> 10.850048 | D27: =VLOOKUP(A27,LQDT!A:G,7,FALSE) -> 1.761736 | E27: =VLOOKUP(A27,OBLG!A:G,7,FALSE) -> 2.3822241
A28: 46035 | B28: =VLOOKUP(A28,EQMX!A:G,7,FALSE) -> 7.8203724 | C28: =VLOOKUP(A28,GOLD!A:G,7,FALSE) -> 10.296084 | D28: =VLOOKUP(A28,LQDT!A:G,7,FALSE) -> 1.8047051 | E28: =VLOOKUP(A28,OBLG!A:G,7,FALSE) -> 2.3715415
A29: 46036 | B29: =VLOOKUP(A29,EQMX!A:G,7,FALSE) -> 8.1489595 | C29: =VLOOKUP(A29,GOLD!A:G,7,FALSE) -> 10.52531 | D29: =VLOOKUP(A29,LQDT!A:G,7,FALSE) -> 1.8530454 | E29: =VLOOKUP(A29,OBLG!A:G,7,FALSE) -> 2.2540327
A30: 46037 | B30: =VLOOKUP(A30,EQMX!A:G,7,FALSE) -> 8.4775465 | C30: =VLOOKUP(A30,GOLD!A:G,7,FALSE) -> 9.3982808 | D30: =VLOOKUP(A30,LQDT!A:G,7,FALSE) -> 1.8960146 | E30: =VLOOKUP(A30,OBLG!A:G,7,FALSE) -> 2.2967632
A31: 46038 | B31: =VLOOKUP(A31,EQMX!A:G,7,FALSE) -> 8.8061336 | C31: =VLOOKUP(A31,GOLD!A:G,7,FALSE) -> 8.9589303 | D31: =VLOOKUP(A31,LQDT!A:G,7,FALSE) -> 2.0249221 | E31: =VLOOKUP(A31,OBLG!A:G,7,FALSE) -> 2.1792544
A32: 46041 | B32: =VLOOKUP(A32,EQMX!A:G,7,FALSE) -> 9.1347207 | C32: =VLOOKUP(A32,GOLD!A:G,7,FALSE) -> 10.754537 | D32: =VLOOKUP(A32,LQDT!A:G,7,FALSE) -> 2.0678913 | E32: =VLOOKUP(A32,OBLG!A:G,7,FALSE) -> 2.2967632
A33: 46042 | B33: =VLOOKUP(A33,EQMX!A:G,7,FALSE) -> 9.4633078 | C33: =VLOOKUP(A33,GOLD!A:G,7,FALSE) -> 13.085005 | D33: =VLOOKUP(A33,LQDT!A:G,7,FALSE) -> 2.1108605 | E33: =VLOOKUP(A33,OBLG!A:G,7,FALSE) -> 2.3715415
A34: 46043 | B34: =VLOOKUP(A34,EQMX!A:G,7,FALSE) -> 9.7918949 | C34: =VLOOKUP(A34,GOLD!A:G,7,FALSE) -> 12.129895 | D34: =VLOOKUP(A34,LQDT!A:G,7,FALSE) -> 2.1538296 | E34: =VLOOKUP(A34,OBLG!A:G,7,FALSE) -> 2.2967632
A35: 46044 | B35: =VLOOKUP(A35,EQMX!A:G,7,FALSE) -> 10.120482 | C35: =VLOOKUP(A35,GOLD!A:G,7,FALSE) -> 13.467049 | D35: =VLOOKUP(A35,LQDT!A:G,7,FALSE) -> 2.2021699 | E35: =VLOOKUP(A35,OBLG!A:G,7,FALSE) -> 2.3501763 | F35: =VLOOKUP(A35,trades_lookback29_mktvol21_2026!A:K,11,FALSE) -> -2.2430687
A36: 46045 | B36: =VLOOKUP(A36,EQMX!A:G,7,FALSE) -> 10.449069 | C36: =VLOOKUP(A36,GOLD!A:G,7,FALSE) -> 14.460363 | D36: =VLOOKUP(A36,LQDT!A:G,7,FALSE) -> 2.3310775 | E36: =VLOOKUP(A36,OBLG!A:G,7,FALSE) -> 2.414272
A37: 46048 | B37: =VLOOKUP(A37,EQMX!A:G,7,FALSE) -> 10.777656 | C37: =VLOOKUP(A37,GOLD!A:G,7,FALSE) -> 17.917861 | D37: =VLOOKUP(A37,LQDT!A:G,7,FALSE) -> 2.3686755 | E37: =VLOOKUP(A37,OBLG!A:G,7,FALSE) -> 2.4783677
A38: 46049 | B38: =VLOOKUP(A38,EQMX!A:G,7,FALSE) -> 11.106243 | C38: =VLOOKUP(A38,GOLD!A:G,7,FALSE) -> 18.949379 | D38: =VLOOKUP(A38,LQDT!A:G,7,FALSE) -> 2.4170158 | E38: =VLOOKUP(A38,OBLG!A:G,7,FALSE) -> 2.7881637 | F38: =VLOOKUP(A38,trades_lookback29_mktvol21_2026!A:K,11,FALSE) -> 2.4781441
A39: 46050 | B39: =VLOOKUP(A39,EQMX!A:G,7,FALSE) -> 11.43483 | C39: =VLOOKUP(A39,GOLD!A:G,7,FALSE) -> 25.253104 | D39: =VLOOKUP(A39,LQDT!A:G,7,FALSE) -> 2.459985 | E39: =VLOOKUP(A39,OBLG!A:G,7,FALSE) -> 2.7347506
A40: 46051 | B40: =VLOOKUP(A40,EQMX!A:G,7,FALSE) -> 11.763417 | C40: =VLOOKUP(A40,GOLD!A:G,7,FALSE) -> 22.674308 | D40: =VLOOKUP(A40,LQDT!A:G,7,FALSE) -> 2.5029541 | E40: =VLOOKUP(A40,OBLG!A:G,7,FALSE) -> 2.7240679 | F40: =VLOOKUP(A40,trades_lookback29_mktvol21_2026!A:K,11,FALSE) -> 2.4121833
...

Sheet GOLD
A1: TRADEDATE | B1: OPEN | C1: HIGH | D1: LOW | E1: CLOSE | F1: VOLUME | G1: result
A2: 45993 | B2: 2.6205 | C2: 2.6315 | D2: 2.595 | E2: 2.6175 | F2: 32249101
A3: 45994 | B3: 2.623 | C3: 2.636 | D3: 2.5885 | E3: 2.593 | F3: 22016391 | G3: =(E3-$E$2)/$E$2*100 -> -0.93600764
A4: 45995 | B4: 2.5895 | C4: 2.5965 | D4: 2.554 | E4: 2.5615 | F4: 37491292 | G4: =(E4-$E$2)/$E$2*100 -> -2.139446
A5: 45996 | B5: 2.565 | C5: 2.6075 | D5: 2.565 | E5: 2.5895 | F5: 47327319 | G5: =(E5-$E$2)/$E$2*100 -> -1.069723
A6: 45999 | B6: 2.6 | C6: 2.614 | D6: 2.576 | E6: 2.5895 | F6: 29396373 | G6: =(E6-$E$2)/$E$2*100 -> -1.069723
A7: 46000 | B7: 2.5885 | C7: 2.626 | D7: 2.5775 | E7: 2.613 | F7: 16396313 | G7: =(E7-$E$2)/$E$2*100 -> -0.17191977
A8: 46001 | B8: 2.617 | C8: 2.65 | D8: 2.6025 | E8: 2.6495 | F8: 23941152 | G8: =(E8-$E$2)/$E$2*100 -> 1.2225406
A9: 46002 | B9: 2.6495 | C9: 2.709 | D9: 2.6275 | E9: 2.686 | F9: 56128465 | G9: =(E9-$E$2)/$E$2*100 -> 2.617001
A10: 46003 | B10: 2.68 | C10: 2.74 | D10: 2.674 | E10: 2.6955 | F10: 43013721 | G10: =(E10-$E$2)/$E$2*100 -> 2.9799427
A11: 46006 | B11: 2.714 | C11: 2.7335 | D11: 2.704 | E11: 2.719 | F11: 45434012 | G11: =(E11-$E$2)/$E$2*100 -> 3.8777459
A12: 46007 | B12: 2.714 | C12: 2.718 | D12: 2.6875 | E12: 2.713 | F12: 26486611 | G12: =(E12-$E$2)/$E$2*100 -> 3.6485196
A13: 46008 | B13: 2.7195 | C13: 2.74 | D13: 2.715 | E13: 2.734 | F13: 38361684 | G13: =(E13-$E$2)/$E$2*100 -> 4.4508118
A14: 46009 | B14: 2.734 | C14: 2.761 | D14: 2.7005 | E14: 2.7375 | F14: 129006695 | G14: =(E14-$E$2)/$E$2*100 -> 4.5845272
... A51: 46066 | B51: 3.11 | C51: 3.132 | D51: 3.064 | E51: 3.1255 | F51: 76538646 | G51: =(E51-$E$2)/$E$2*100 -> 19.407832

Sheet LQDT
A1: TRADEDATE | B1: OPEN | C1: HIGH | D1: LOW | E1: CLOSE | F1: VOLUME | G1: result
A2: 45993 | B2: 1.8617 | C2: 1.8618 | D2: 1.8617 | E2: 1.8618 | F2: 5567744349
A3: 45994 | B3: 1.8625 | C3: 1.8626 | D3: 1.8625 | E3: 1.8626 | F3: 6081525394 | G3: =(E3-$E$2)/$E$2*100 -> 0.04296917
A4: 45995 | B4: 1.8633 | C4: 1.8633 | D4: 1.8632 | E4: 1.8633 | F4: 7578109065 | G4: =(E4-$E$2)/$E$2*100 -> 0.080567193
A5: 45996 | B5: 1.8657 | C5: 1.8657 | D5: 1.8656 | E5: 1.8657 | F5: 8424361813 | G5: =(E5-$E$2)/$E$2*100 -> 0.2094747
A6: 45999 | B6: 1.8665 | C6: 1.8665 | D6: 1.8664 | E6: 1.8664 | F6: 7776231631 | G6: =(E6-$E$2)/$E$2*100 -> 0.24707273
A7: 46000 | B7: 1.8673 | C7: 1.8674 | D7: 1.8673 | E7: 1.8673 | F7: 5000275445 | G7: =(E7-$E$2)/$E$2*100 -> 0.29541304
A8: 46001 | B8: 1.8681 | C8: 1.8682 | D8: 1.8681 | E8: 1.8682 | F8: 6069308375 | G8: =(E8-$E$2)/$E$2*100 -> 0.34375336
A9: 46002 | B9: 1.8689 | C9: 1.869 | D9: 1.8689 | E9: 1.869 | F9: 7036841421 | G9: =(E9-$E$2)/$E$2*100 -> 0.38672253
A10: 46003 | B10: 1.8714 | C10: 1.8714 | D10: 1.8713 | E10: 1.8714 | F10: 6800233028 | G10: =(E10-$E$2)/$E$2*100 -> 0.51563004
A11: 46006 | B11: 1.8721 | C11: 1.8722 | D11: 1.8721 | E11: 1.8721 | F11: 8661056525 | G11: =(E11-$E$2)/$E$2*100 -> 0.55322806
A12: 46007 | B12: 1.873 | C12: 1.8731 | D12: 1.8729 | E12: 1.8729 | F12: 7585622120 | G12: =(E12-$E$2)/$E$2*100 -> 0.59619723
A13: 46008 | B13: 1.8737 | C13: 1.8738 | D13: 1.8737 | E13: 1.8737 | F13: 6892215860 | G13: =(E13-$E$2)/$E$2*100 -> 0.6391664
A14: 46009 | B14: 1.8745 | C14: 1.8746 | D14: 1.8745 | E14: 1.8745 | F14: 9444982357 | G14: =(E14-$E$2)/$E$2*100 -> 0.68213557
... A51: 46066 | B51: 1.9219 | C51: 1.922 | D51: 1.9219 | E51: 1.922 | F51: 5992626747 | G51: =(E51-$E$2)/$E$2*100 -> 3.23343

Sheet OBLG
A1: TRADEDATE | B1: OPEN | C1: HIGH | D1: LOW | E1: CLOSE | F1: VOLUME | G1: result
A2: 45993 | B2: 187.26 | C2: 187.3 | D2: 186.82 | E2: 187.22 | F2: 103838
A3: 45994 | B3: 187.22 | C3: 187.5 | D3: 187.02 | E3: 187.28 | F3: 99413 | G3: =(E3-$E$2)/$E$2*100 -> 0.032047858
A4: 45995 | B4: 187.36 | C4: 187.5 | D4: 187 | E4: 187.18 | F4: 212174 | G4: =(E4-$E$2)/$E$2*100 -> -0.021365239
A5: 45996 | B5: 187.18 | C5: 187.62 | D5: 187 | E5: 187.62 | F5: 187220 | G5: =(E5-$E$2)/$E$2*100 -> 0.21365239
A6: 45999 | B6: 187.68 | C6: 188.5 | D6: 187.26 | E6: 187.44 | F6: 153472 | G6: =(E6-$E$2)/$E$2*100 -> 0.11750881
A7: 46000 | B7: 187.6 | C7: 187.7 | D7: 187.4 | E7: 187.5 | F7: 80893 | G7: =(E7-$E$2)/$E$2*100 -> 0.14955667
A8: 46001 | B8: 187.8 | C8: 188.5 | D8: 187.5 | E8: 188.16 | F8: 241729 | G8: =(E8-$E$2)/$E$2*100 -> 0.50208311
A9: 46002 | B9: 188.16 | C9: 188.52 | D9: 187.9 | E9: 188.12 | F9: 127714 | G9: =(E9-$E$2)/$E$2*100 -> 0.48071787
A10: 46003 | B10: 188.5 | C10: 188.74 | D10: 188.14 | E10: 188.62 | F10: 128170 | G10: =(E10-$E$2)/$E$2*100 -> 0.74778336
A11: 46006 | B11: 188.76 | C11: 189.2 | D11: 188.62 | E11: 188.92 | F11: 141040 | G11: =(E11-$E$2)/$E$2*100 -> 0.90802265
A12: 46007 | B12: 188.92 | C12: 189.12 | D12: 188.7 | E12: 188.96 | F12: 100043 | G12: =(E12-$E$2)/$E$2*100 -> 0.92938789
A13: 46008 | B13: 188.98 | C13: 189.22 | D13: 188.8 | E13: 189.16 | F13: 152240 | G13: =(E13-$E$2)/$E$2*100 -> 1.0362141
A14: 46009 | B14: 189.34 | C14: 189.56 | D14: 189.08 | E14: 189.56 | F14: 253500 | G14: =(E14-$E$2)/$E$2*100 -> 1.2498665
... A51: 46066 | B51: 193.6 | C51: 194.1 | D51: 193.6 | E51: 194.04 | F51: 458941 | G51: =(E51-$E$2)/$E$2*100 -> 3.6427732
